2025-10-07 23:23:47,348 - ERROR - Exception in callback BaseIOStream.write.<locals>.<lambda>(<Future cancelled>) at C:\Users\ch3njay\anaconda3\lib\site-packages\tornado\iostream.py:536
handle: <Handle BaseIOStream.write.<locals>.<lambda>(<Future cancelled>) at C:\Users\ch3njay\anaconda3\lib\site-packages\tornado\iostream.py:536>
Traceback (most recent call last):
  File "C:\Users\ch3njay\anaconda3\lib\asyncio\events.py", line 80, in _run
    self._context.run(self._callback, *self._args)
  File "C:\Users\ch3njay\anaconda3\lib\site-packages\tornado\iostream.py", line 536, in <lambda>
    future.add_done_callback(lambda f: f.exception())
asyncio.exceptions.CancelledError
2025-10-07 23:23:47,369 - ERROR - Exception in callback BaseIOStream.write.<locals>.<lambda>(<Future cancelled>) at C:\Users\ch3njay\anaconda3\lib\site-packages\tornado\iostream.py:536
handle: <Handle BaseIOStream.write.<locals>.<lambda>(<Future cancelled>) at C:\Users\ch3njay\anaconda3\lib\site-packages\tornado\iostream.py:536>
Traceback (most recent call last):
  File "C:\Users\ch3njay\anaconda3\lib\asyncio\events.py", line 80, in _run
    self._context.run(self._callback, *self._args)
  File "C:\Users\ch3njay\anaconda3\lib\site-packages\tornado\iostream.py", line 536, in <lambda>
    future.add_done_callback(lambda f: f.exception())
asyncio.exceptions.CancelledError
2025-10-07 23:23:47,370 - ERROR - Exception in callback BaseIOStream.write.<locals>.<lambda>(<Future cancelled>) at C:\Users\ch3njay\anaconda3\lib\site-packages\tornado\iostream.py:536
handle: <Handle BaseIOStream.write.<locals>.<lambda>(<Future cancelled>) at C:\Users\ch3njay\anaconda3\lib\site-packages\tornado\iostream.py:536>
Traceback (most recent call last):
  File "C:\Users\ch3njay\anaconda3\lib\asyncio\events.py", line 80, in _run
    self._context.run(self._callback, *self._args)
  File "C:\Users\ch3njay\anaconda3\lib\site-packages\tornado\iostream.py", line 536, in <lambda>
    future.add_done_callback(lambda f: f.exception())
asyncio.exceptions.CancelledError
2025-10-07 23:23:47,372 - ERROR - Exception in callback BaseIOStream.write.<locals>.<lambda>(<Future cancelled>) at C:\Users\ch3njay\anaconda3\lib\site-packages\tornado\iostream.py:536
handle: <Handle BaseIOStream.write.<locals>.<lambda>(<Future cancelled>) at C:\Users\ch3njay\anaconda3\lib\site-packages\tornado\iostream.py:536>
Traceback (most recent call last):
  File "C:\Users\ch3njay\anaconda3\lib\asyncio\events.py", line 80, in _run
    self._context.run(self._callback, *self._args)
  File "C:\Users\ch3njay\anaconda3\lib\site-packages\tornado\iostream.py", line 536, in <lambda>
    future.add_done_callback(lambda f: f.exception())
asyncio.exceptions.CancelledError
2025-10-07 23:23:47,374 - ERROR - Exception in callback BaseIOStream.write.<locals>.<lambda>(<Future cancelled>) at C:\Users\ch3njay\anaconda3\lib\site-packages\tornado\iostream.py:536
handle: <Handle BaseIOStream.write.<locals>.<lambda>(<Future cancelled>) at C:\Users\ch3njay\anaconda3\lib\site-packages\tornado\iostream.py:536>
Traceback (most recent call last):
  File "C:\Users\ch3njay\anaconda3\lib\asyncio\events.py", line 80, in _run
    self._context.run(self._callback, *self._args)
  File "C:\Users\ch3njay\anaconda3\lib\site-packages\tornado\iostream.py", line 536, in <lambda>
    future.add_done_callback(lambda f: f.exception())
asyncio.exceptions.CancelledError
2025-10-07 23:23:47,377 - ERROR - Exception in callback BaseIOStream.write.<locals>.<lambda>(<Future cancelled>) at C:\Users\ch3njay\anaconda3\lib\site-packages\tornado\iostream.py:536
handle: <Handle BaseIOStream.write.<locals>.<lambda>(<Future cancelled>) at C:\Users\ch3njay\anaconda3\lib\site-packages\tornado\iostream.py:536>
Traceback (most recent call last):
  File "C:\Users\ch3njay\anaconda3\lib\asyncio\events.py", line 80, in _run
    self._context.run(self._callback, *self._args)
  File "C:\Users\ch3njay\anaconda3\lib\site-packages\tornado\iostream.py", line 536, in <lambda>
    future.add_done_callback(lambda f: f.exception())
asyncio.exceptions.CancelledError
2025-10-07 23:23:47,379 - ERROR - Exception in callback BaseIOStream.write.<locals>.<lambda>(<Future cancelled>) at C:\Users\ch3njay\anaconda3\lib\site-packages\tornado\iostream.py:536
handle: <Handle BaseIOStream.write.<locals>.<lambda>(<Future cancelled>) at C:\Users\ch3njay\anaconda3\lib\site-packages\tornado\iostream.py:536>
Traceback (most recent call last):
  File "C:\Users\ch3njay\anaconda3\lib\asyncio\events.py", line 80, in _run
    self._context.run(self._callback, *self._args)
  File "C:\Users\ch3njay\anaconda3\lib\site-packages\tornado\iostream.py", line 536, in <lambda>
    future.add_done_callback(lambda f: f.exception())
asyncio.exceptions.CancelledError
2025-10-07 23:23:47,381 - ERROR - Exception in callback BaseIOStream.write.<locals>.<lambda>(<Future cancelled>) at C:\Users\ch3njay\anaconda3\lib\site-packages\tornado\iostream.py:536
handle: <Handle BaseIOStream.write.<locals>.<lambda>(<Future cancelled>) at C:\Users\ch3njay\anaconda3\lib\site-packages\tornado\iostream.py:536>
Traceback (most recent call last):
  File "C:\Users\ch3njay\anaconda3\lib\asyncio\events.py", line 80, in _run
    self._context.run(self._callback, *self._args)
  File "C:\Users\ch3njay\anaconda3\lib\site-packages\tornado\iostream.py", line 536, in <lambda>
    future.add_done_callback(lambda f: f.exception())
asyncio.exceptions.CancelledError
2025-10-07 23:23:47,383 - ERROR - Exception in callback BaseIOStream.write.<locals>.<lambda>(<Future cancelled>) at C:\Users\ch3njay\anaconda3\lib\site-packages\tornado\iostream.py:536
handle: <Handle BaseIOStream.write.<locals>.<lambda>(<Future cancelled>) at C:\Users\ch3njay\anaconda3\lib\site-packages\tornado\iostream.py:536>
Traceback (most recent call last):
  File "C:\Users\ch3njay\anaconda3\lib\asyncio\events.py", line 80, in _run
    self._context.run(self._callback, *self._args)
  File "C:\Users\ch3njay\anaconda3\lib\site-packages\tornado\iostream.py", line 536, in <lambda>
    future.add_done_callback(lambda f: f.exception())
asyncio.exceptions.CancelledError
2025-10-07 23:23:47,384 - ERROR - Exception in callback BaseIOStream.write.<locals>.<lambda>(<Future cancelled>) at C:\Users\ch3njay\anaconda3\lib\site-packages\tornado\iostream.py:536
handle: <Handle BaseIOStream.write.<locals>.<lambda>(<Future cancelled>) at C:\Users\ch3njay\anaconda3\lib\site-packages\tornado\iostream.py:536>
Traceback (most recent call last):
  File "C:\Users\ch3njay\anaconda3\lib\asyncio\events.py", line 80, in _run
    self._context.run(self._callback, *self._args)
  File "C:\Users\ch3njay\anaconda3\lib\site-packages\tornado\iostream.py", line 536, in <lambda>
    future.add_done_callback(lambda f: f.exception())
asyncio.exceptions.CancelledError
2025-10-07 23:23:47,385 - ERROR - Exception in callback BaseIOStream.write.<locals>.<lambda>(<Future cancelled>) at C:\Users\ch3njay\anaconda3\lib\site-packages\tornado\iostream.py:536
handle: <Handle BaseIOStream.write.<locals>.<lambda>(<Future cancelled>) at C:\Users\ch3njay\anaconda3\lib\site-packages\tornado\iostream.py:536>
Traceback (most recent call last):
  File "C:\Users\ch3njay\anaconda3\lib\asyncio\events.py", line 80, in _run
    self._context.run(self._callback, *self._args)
  File "C:\Users\ch3njay\anaconda3\lib\site-packages\tornado\iostream.py", line 536, in <lambda>
    future.add_done_callback(lambda f: f.exception())
asyncio.exceptions.CancelledError
2025-10-07 23:23:47,386 - ERROR - Exception in callback BaseIOStream.write.<locals>.<lambda>(<Future cancelled>) at C:\Users\ch3njay\anaconda3\lib\site-packages\tornado\iostream.py:536
handle: <Handle BaseIOStream.write.<locals>.<lambda>(<Future cancelled>) at C:\Users\ch3njay\anaconda3\lib\site-packages\tornado\iostream.py:536>
Traceback (most recent call last):
  File "C:\Users\ch3njay\anaconda3\lib\asyncio\events.py", line 80, in _run
    self._context.run(self._callback, *self._args)
  File "C:\Users\ch3njay\anaconda3\lib\site-packages\tornado\iostream.py", line 536, in <lambda>
    future.add_done_callback(lambda f: f.exception())
asyncio.exceptions.CancelledError
2025-10-07 23:23:47,387 - ERROR - Exception in callback BaseIOStream.write.<locals>.<lambda>(<Future cancelled>) at C:\Users\ch3njay\anaconda3\lib\site-packages\tornado\iostream.py:536
handle: <Handle BaseIOStream.write.<locals>.<lambda>(<Future cancelled>) at C:\Users\ch3njay\anaconda3\lib\site-packages\tornado\iostream.py:536>
Traceback (most recent call last):
  File "C:\Users\ch3njay\anaconda3\lib\asyncio\events.py", line 80, in _run
    self._context.run(self._callback, *self._args)
  File "C:\Users\ch3njay\anaconda3\lib\site-packages\tornado\iostream.py", line 536, in <lambda>
    future.add_done_callback(lambda f: f.exception())
asyncio.exceptions.CancelledError
2025-10-07 23:23:47,389 - ERROR - Exception in callback BaseIOStream.write.<locals>.<lambda>(<Future cancelled>) at C:\Users\ch3njay\anaconda3\lib\site-packages\tornado\iostream.py:536
handle: <Handle BaseIOStream.write.<locals>.<lambda>(<Future cancelled>) at C:\Users\ch3njay\anaconda3\lib\site-packages\tornado\iostream.py:536>
Traceback (most recent call last):
  File "C:\Users\ch3njay\anaconda3\lib\asyncio\events.py", line 80, in _run
    self._context.run(self._callback, *self._args)
  File "C:\Users\ch3njay\anaconda3\lib\site-packages\tornado\iostream.py", line 536, in <lambda>
    future.add_done_callback(lambda f: f.exception())
asyncio.exceptions.CancelledError
2025-10-07 23:23:47,390 - ERROR - Exception in callback BaseIOStream.write.<locals>.<lambda>(<Future cancelled>) at C:\Users\ch3njay\anaconda3\lib\site-packages\tornado\iostream.py:536
handle: <Handle BaseIOStream.write.<locals>.<lambda>(<Future cancelled>) at C:\Users\ch3njay\anaconda3\lib\site-packages\tornado\iostream.py:536>
Traceback (most recent call last):
  File "C:\Users\ch3njay\anaconda3\lib\asyncio\events.py", line 80, in _run
    self._context.run(self._callback, *self._args)
  File "C:\Users\ch3njay\anaconda3\lib\site-packages\tornado\iostream.py", line 536, in <lambda>
    future.add_done_callback(lambda f: f.exception())
asyncio.exceptions.CancelledError
2025-10-07 23:23:47,390 - ERROR - Exception in callback BaseIOStream.write.<locals>.<lambda>(<Future cancelled>) at C:\Users\ch3njay\anaconda3\lib\site-packages\tornado\iostream.py:536
handle: <Handle BaseIOStream.write.<locals>.<lambda>(<Future cancelled>) at C:\Users\ch3njay\anaconda3\lib\site-packages\tornado\iostream.py:536>
Traceback (most recent call last):
  File "C:\Users\ch3njay\anaconda3\lib\asyncio\events.py", line 80, in _run
    self._context.run(self._callback, *self._args)
  File "C:\Users\ch3njay\anaconda3\lib\site-packages\tornado\iostream.py", line 536, in <lambda>
    future.add_done_callback(lambda f: f.exception())
asyncio.exceptions.CancelledError
2025-10-07 23:23:47,390 - ERROR - Exception in callback BaseIOStream.write.<locals>.<lambda>(<Future cancelled>) at C:\Users\ch3njay\anaconda3\lib\site-packages\tornado\iostream.py:536
handle: <Handle BaseIOStream.write.<locals>.<lambda>(<Future cancelled>) at C:\Users\ch3njay\anaconda3\lib\site-packages\tornado\iostream.py:536>
Traceback (most recent call last):
  File "C:\Users\ch3njay\anaconda3\lib\asyncio\events.py", line 80, in _run
    self._context.run(self._callback, *self._args)
  File "C:\Users\ch3njay\anaconda3\lib\site-packages\tornado\iostream.py", line 536, in <lambda>
    future.add_done_callback(lambda f: f.exception())
asyncio.exceptions.CancelledError
2025-10-07 23:23:47,395 - ERROR - Exception in callback BaseIOStream.write.<locals>.<lambda>(<Future cancelled>) at C:\Users\ch3njay\anaconda3\lib\site-packages\tornado\iostream.py:536
handle: <Handle BaseIOStream.write.<locals>.<lambda>(<Future cancelled>) at C:\Users\ch3njay\anaconda3\lib\site-packages\tornado\iostream.py:536>
Traceback (most recent call last):
  File "C:\Users\ch3njay\anaconda3\lib\asyncio\events.py", line 80, in _run
    self._context.run(self._callback, *self._args)
  File "C:\Users\ch3njay\anaconda3\lib\site-packages\tornado\iostream.py", line 536, in <lambda>
    future.add_done_callback(lambda f: f.exception())
asyncio.exceptions.CancelledError
2025-10-07 23:23:47,398 - ERROR - Exception in callback BaseIOStream.write.<locals>.<lambda>(<Future cancelled>) at C:\Users\ch3njay\anaconda3\lib\site-packages\tornado\iostream.py:536
handle: <Handle BaseIOStream.write.<locals>.<lambda>(<Future cancelled>) at C:\Users\ch3njay\anaconda3\lib\site-packages\tornado\iostream.py:536>
Traceback (most recent call last):
  File "C:\Users\ch3njay\anaconda3\lib\asyncio\events.py", line 80, in _run
    self._context.run(self._callback, *self._args)
  File "C:\Users\ch3njay\anaconda3\lib\site-packages\tornado\iostream.py", line 536, in <lambda>
    future.add_done_callback(lambda f: f.exception())
asyncio.exceptions.CancelledError
2025-10-07 23:23:47,405 - ERROR - Exception in callback BaseIOStream.write.<locals>.<lambda>(<Future cancelled>) at C:\Users\ch3njay\anaconda3\lib\site-packages\tornado\iostream.py:536
handle: <Handle BaseIOStream.write.<locals>.<lambda>(<Future cancelled>) at C:\Users\ch3njay\anaconda3\lib\site-packages\tornado\iostream.py:536>
Traceback (most recent call last):
  File "C:\Users\ch3njay\anaconda3\lib\asyncio\events.py", line 80, in _run
    self._context.run(self._callback, *self._args)
  File "C:\Users\ch3njay\anaconda3\lib\site-packages\tornado\iostream.py", line 536, in <lambda>
    future.add_done_callback(lambda f: f.exception())
asyncio.exceptions.CancelledError
2025-10-07 23:23:47,407 - ERROR - Exception in callback BaseIOStream.write.<locals>.<lambda>(<Future cancelled>) at C:\Users\ch3njay\anaconda3\lib\site-packages\tornado\iostream.py:536
handle: <Handle BaseIOStream.write.<locals>.<lambda>(<Future cancelled>) at C:\Users\ch3njay\anaconda3\lib\site-packages\tornado\iostream.py:536>
Traceback (most recent call last):
  File "C:\Users\ch3njay\anaconda3\lib\asyncio\events.py", line 80, in _run
    self._context.run(self._callback, *self._args)
  File "C:\Users\ch3njay\anaconda3\lib\site-packages\tornado\iostream.py", line 536, in <lambda>
    future.add_done_callback(lambda f: f.exception())
asyncio.exceptions.CancelledError
2025-10-07 23:23:47,411 - ERROR - Exception in callback BaseIOStream.write.<locals>.<lambda>(<Future cancelled>) at C:\Users\ch3njay\anaconda3\lib\site-packages\tornado\iostream.py:536
handle: <Handle BaseIOStream.write.<locals>.<lambda>(<Future cancelled>) at C:\Users\ch3njay\anaconda3\lib\site-packages\tornado\iostream.py:536>
Traceback (most recent call last):
  File "C:\Users\ch3njay\anaconda3\lib\asyncio\events.py", line 80, in _run
    self._context.run(self._callback, *self._args)
  File "C:\Users\ch3njay\anaconda3\lib\site-packages\tornado\iostream.py", line 536, in <lambda>
    future.add_done_callback(lambda f: f.exception())
asyncio.exceptions.CancelledError
2025-10-07 23:23:47,417 - ERROR - Exception in callback BaseIOStream.write.<locals>.<lambda>(<Future cancelled>) at C:\Users\ch3njay\anaconda3\lib\site-packages\tornado\iostream.py:536
handle: <Handle BaseIOStream.write.<locals>.<lambda>(<Future cancelled>) at C:\Users\ch3njay\anaconda3\lib\site-packages\tornado\iostream.py:536>
Traceback (most recent call last):
  File "C:\Users\ch3njay\anaconda3\lib\asyncio\events.py", line 80, in _run
    self._context.run(self._callback, *self._args)
  File "C:\Users\ch3njay\anaconda3\lib\site-packages\tornado\iostream.py", line 536, in <lambda>
    future.add_done_callback(lambda f: f.exception())
asyncio.exceptions.CancelledError
2025-10-07 23:23:47,420 - ERROR - Exception in callback BaseIOStream.write.<locals>.<lambda>(<Future cancelled>) at C:\Users\ch3njay\anaconda3\lib\site-packages\tornado\iostream.py:536
handle: <Handle BaseIOStream.write.<locals>.<lambda>(<Future cancelled>) at C:\Users\ch3njay\anaconda3\lib\site-packages\tornado\iostream.py:536>
Traceback (most recent call last):
  File "C:\Users\ch3njay\anaconda3\lib\asyncio\events.py", line 80, in _run
    self._context.run(self._callback, *self._args)
  File "C:\Users\ch3njay\anaconda3\lib\site-packages\tornado\iostream.py", line 536, in <lambda>
    future.add_done_callback(lambda f: f.exception())
asyncio.exceptions.CancelledError
2025-10-07 23:23:47,424 - ERROR - Exception in callback BaseIOStream.write.<locals>.<lambda>(<Future cancelled>) at C:\Users\ch3njay\anaconda3\lib\site-packages\tornado\iostream.py:536
handle: <Handle BaseIOStream.write.<locals>.<lambda>(<Future cancelled>) at C:\Users\ch3njay\anaconda3\lib\site-packages\tornado\iostream.py:536>
Traceback (most recent call last):
  File "C:\Users\ch3njay\anaconda3\lib\asyncio\events.py", line 80, in _run
    self._context.run(self._callback, *self._args)
  File "C:\Users\ch3njay\anaconda3\lib\site-packages\tornado\iostream.py", line 536, in <lambda>
    future.add_done_callback(lambda f: f.exception())
asyncio.exceptions.CancelledError
2025-10-07 23:23:47,426 - ERROR - Exception in callback BaseIOStream.write.<locals>.<lambda>(<Future cancelled>) at C:\Users\ch3njay\anaconda3\lib\site-packages\tornado\iostream.py:536
handle: <Handle BaseIOStream.write.<locals>.<lambda>(<Future cancelled>) at C:\Users\ch3njay\anaconda3\lib\site-packages\tornado\iostream.py:536>
Traceback (most recent call last):
  File "C:\Users\ch3njay\anaconda3\lib\asyncio\events.py", line 80, in _run
    self._context.run(self._callback, *self._args)
  File "C:\Users\ch3njay\anaconda3\lib\site-packages\tornado\iostream.py", line 536, in <lambda>
    future.add_done_callback(lambda f: f.exception())
asyncio.exceptions.CancelledError
2025-10-07 23:23:47,427 - ERROR - Exception in callback BaseIOStream.write.<locals>.<lambda>(<Future cancelled>) at C:\Users\ch3njay\anaconda3\lib\site-packages\tornado\iostream.py:536
handle: <Handle BaseIOStream.write.<locals>.<lambda>(<Future cancelled>) at C:\Users\ch3njay\anaconda3\lib\site-packages\tornado\iostream.py:536>
Traceback (most recent call last):
  File "C:\Users\ch3njay\anaconda3\lib\asyncio\events.py", line 80, in _run
    self._context.run(self._callback, *self._args)
  File "C:\Users\ch3njay\anaconda3\lib\site-packages\tornado\iostream.py", line 536, in <lambda>
    future.add_done_callback(lambda f: f.exception())
asyncio.exceptions.CancelledError
2025-10-07 23:23:47,427 - ERROR - Exception in callback BaseIOStream.write.<locals>.<lambda>(<Future cancelled>) at C:\Users\ch3njay\anaconda3\lib\site-packages\tornado\iostream.py:536
handle: <Handle BaseIOStream.write.<locals>.<lambda>(<Future cancelled>) at C:\Users\ch3njay\anaconda3\lib\site-packages\tornado\iostream.py:536>
Traceback (most recent call last):
  File "C:\Users\ch3njay\anaconda3\lib\asyncio\events.py", line 80, in _run
    self._context.run(self._callback, *self._args)
  File "C:\Users\ch3njay\anaconda3\lib\site-packages\tornado\iostream.py", line 536, in <lambda>
    future.add_done_callback(lambda f: f.exception())
asyncio.exceptions.CancelledError
2025-10-07 23:23:47,429 - ERROR - Exception in callback BaseIOStream.write.<locals>.<lambda>(<Future cancelled>) at C:\Users\ch3njay\anaconda3\lib\site-packages\tornado\iostream.py:536
handle: <Handle BaseIOStream.write.<locals>.<lambda>(<Future cancelled>) at C:\Users\ch3njay\anaconda3\lib\site-packages\tornado\iostream.py:536>
Traceback (most recent call last):
  File "C:\Users\ch3njay\anaconda3\lib\asyncio\events.py", line 80, in _run
    self._context.run(self._callback, *self._args)
  File "C:\Users\ch3njay\anaconda3\lib\site-packages\tornado\iostream.py", line 536, in <lambda>
    future.add_done_callback(lambda f: f.exception())
asyncio.exceptions.CancelledError
2025-10-07 23:23:47,432 - ERROR - Exception in callback BaseIOStream.write.<locals>.<lambda>(<Future cancelled>) at C:\Users\ch3njay\anaconda3\lib\site-packages\tornado\iostream.py:536
handle: <Handle BaseIOStream.write.<locals>.<lambda>(<Future cancelled>) at C:\Users\ch3njay\anaconda3\lib\site-packages\tornado\iostream.py:536>
Traceback (most recent call last):
  File "C:\Users\ch3njay\anaconda3\lib\asyncio\events.py", line 80, in _run
    self._context.run(self._callback, *self._args)
  File "C:\Users\ch3njay\anaconda3\lib\site-packages\tornado\iostream.py", line 536, in <lambda>
    future.add_done_callback(lambda f: f.exception())
asyncio.exceptions.CancelledError
2025-10-07 23:23:47,433 - ERROR - Exception in callback BaseIOStream.write.<locals>.<lambda>(<Future cancelled>) at C:\Users\ch3njay\anaconda3\lib\site-packages\tornado\iostream.py:536
handle: <Handle BaseIOStream.write.<locals>.<lambda>(<Future cancelled>) at C:\Users\ch3njay\anaconda3\lib\site-packages\tornado\iostream.py:536>
Traceback (most recent call last):
  File "C:\Users\ch3njay\anaconda3\lib\asyncio\events.py", line 80, in _run
    self._context.run(self._callback, *self._args)
  File "C:\Users\ch3njay\anaconda3\lib\site-packages\tornado\iostream.py", line 536, in <lambda>
    future.add_done_callback(lambda f: f.exception())
asyncio.exceptions.CancelledError
2025-10-07 23:23:47,435 - ERROR - Exception in callback BaseIOStream.write.<locals>.<lambda>(<Future cancelled>) at C:\Users\ch3njay\anaconda3\lib\site-packages\tornado\iostream.py:536
handle: <Handle BaseIOStream.write.<locals>.<lambda>(<Future cancelled>) at C:\Users\ch3njay\anaconda3\lib\site-packages\tornado\iostream.py:536>
Traceback (most recent call last):
  File "C:\Users\ch3njay\anaconda3\lib\asyncio\events.py", line 80, in _run
    self._context.run(self._callback, *self._args)
  File "C:\Users\ch3njay\anaconda3\lib\site-packages\tornado\iostream.py", line 536, in <lambda>
    future.add_done_callback(lambda f: f.exception())
asyncio.exceptions.CancelledError
2025-10-07 23:23:47,445 - ERROR - Exception in callback BaseIOStream.write.<locals>.<lambda>(<Future cancelled>) at C:\Users\ch3njay\anaconda3\lib\site-packages\tornado\iostream.py:536
handle: <Handle BaseIOStream.write.<locals>.<lambda>(<Future cancelled>) at C:\Users\ch3njay\anaconda3\lib\site-packages\tornado\iostream.py:536>
Traceback (most recent call last):
  File "C:\Users\ch3njay\anaconda3\lib\asyncio\events.py", line 80, in _run
    self._context.run(self._callback, *self._args)
  File "C:\Users\ch3njay\anaconda3\lib\site-packages\tornado\iostream.py", line 536, in <lambda>
    future.add_done_callback(lambda f: f.exception())
asyncio.exceptions.CancelledError
2025-10-07 23:23:47,446 - ERROR - Exception in callback BaseIOStream.write.<locals>.<lambda>(<Future cancelled>) at C:\Users\ch3njay\anaconda3\lib\site-packages\tornado\iostream.py:536
handle: <Handle BaseIOStream.write.<locals>.<lambda>(<Future cancelled>) at C:\Users\ch3njay\anaconda3\lib\site-packages\tornado\iostream.py:536>
Traceback (most recent call last):
  File "C:\Users\ch3njay\anaconda3\lib\asyncio\events.py", line 80, in _run
    self._context.run(self._callback, *self._args)
  File "C:\Users\ch3njay\anaconda3\lib\site-packages\tornado\iostream.py", line 536, in <lambda>
    future.add_done_callback(lambda f: f.exception())
asyncio.exceptions.CancelledError
2025-10-07 23:23:47,447 - ERROR - Exception in callback BaseIOStream.write.<locals>.<lambda>(<Future cancelled>) at C:\Users\ch3njay\anaconda3\lib\site-packages\tornado\iostream.py:536
handle: <Handle BaseIOStream.write.<locals>.<lambda>(<Future cancelled>) at C:\Users\ch3njay\anaconda3\lib\site-packages\tornado\iostream.py:536>
Traceback (most recent call last):
  File "C:\Users\ch3njay\anaconda3\lib\asyncio\events.py", line 80, in _run
    self._context.run(self._callback, *self._args)
  File "C:\Users\ch3njay\anaconda3\lib\site-packages\tornado\iostream.py", line 536, in <lambda>
    future.add_done_callback(lambda f: f.exception())
asyncio.exceptions.CancelledError
2025-10-07 23:23:47,448 - ERROR - Exception in callback BaseIOStream.write.<locals>.<lambda>(<Future cancelled>) at C:\Users\ch3njay\anaconda3\lib\site-packages\tornado\iostream.py:536
handle: <Handle BaseIOStream.write.<locals>.<lambda>(<Future cancelled>) at C:\Users\ch3njay\anaconda3\lib\site-packages\tornado\iostream.py:536>
Traceback (most recent call last):
  File "C:\Users\ch3njay\anaconda3\lib\asyncio\events.py", line 80, in _run
    self._context.run(self._callback, *self._args)
  File "C:\Users\ch3njay\anaconda3\lib\site-packages\tornado\iostream.py", line 536, in <lambda>
    future.add_done_callback(lambda f: f.exception())
asyncio.exceptions.CancelledError
2025-10-07 23:23:47,448 - ERROR - Exception in callback BaseIOStream.write.<locals>.<lambda>(<Future cancelled>) at C:\Users\ch3njay\anaconda3\lib\site-packages\tornado\iostream.py:536
handle: <Handle BaseIOStream.write.<locals>.<lambda>(<Future cancelled>) at C:\Users\ch3njay\anaconda3\lib\site-packages\tornado\iostream.py:536>
Traceback (most recent call last):
  File "C:\Users\ch3njay\anaconda3\lib\asyncio\events.py", line 80, in _run
    self._context.run(self._callback, *self._args)
  File "C:\Users\ch3njay\anaconda3\lib\site-packages\tornado\iostream.py", line 536, in <lambda>
    future.add_done_callback(lambda f: f.exception())
asyncio.exceptions.CancelledError
2025-10-07 23:23:47,449 - ERROR - Exception in callback BaseIOStream.write.<locals>.<lambda>(<Future cancelled>) at C:\Users\ch3njay\anaconda3\lib\site-packages\tornado\iostream.py:536
handle: <Handle BaseIOStream.write.<locals>.<lambda>(<Future cancelled>) at C:\Users\ch3njay\anaconda3\lib\site-packages\tornado\iostream.py:536>
Traceback (most recent call last):
  File "C:\Users\ch3njay\anaconda3\lib\asyncio\events.py", line 80, in _run
    self._context.run(self._callback, *self._args)
  File "C:\Users\ch3njay\anaconda3\lib\site-packages\tornado\iostream.py", line 536, in <lambda>
    future.add_done_callback(lambda f: f.exception())
asyncio.exceptions.CancelledError
2025-10-07 23:23:47,450 - ERROR - Exception in callback BaseIOStream.write.<locals>.<lambda>(<Future cancelled>) at C:\Users\ch3njay\anaconda3\lib\site-packages\tornado\iostream.py:536
handle: <Handle BaseIOStream.write.<locals>.<lambda>(<Future cancelled>) at C:\Users\ch3njay\anaconda3\lib\site-packages\tornado\iostream.py:536>
Traceback (most recent call last):
  File "C:\Users\ch3njay\anaconda3\lib\asyncio\events.py", line 80, in _run
    self._context.run(self._callback, *self._args)
  File "C:\Users\ch3njay\anaconda3\lib\site-packages\tornado\iostream.py", line 536, in <lambda>
    future.add_done_callback(lambda f: f.exception())
asyncio.exceptions.CancelledError
2025-10-07 23:23:47,450 - ERROR - Exception in callback BaseIOStream.write.<locals>.<lambda>(<Future cancelled>) at C:\Users\ch3njay\anaconda3\lib\site-packages\tornado\iostream.py:536
handle: <Handle BaseIOStream.write.<locals>.<lambda>(<Future cancelled>) at C:\Users\ch3njay\anaconda3\lib\site-packages\tornado\iostream.py:536>
Traceback (most recent call last):
  File "C:\Users\ch3njay\anaconda3\lib\asyncio\events.py", line 80, in _run
    self._context.run(self._callback, *self._args)
  File "C:\Users\ch3njay\anaconda3\lib\site-packages\tornado\iostream.py", line 536, in <lambda>
    future.add_done_callback(lambda f: f.exception())
asyncio.exceptions.CancelledError
2025-10-07 23:23:47,450 - ERROR - Exception in callback BaseIOStream.write.<locals>.<lambda>(<Future cancelled>) at C:\Users\ch3njay\anaconda3\lib\site-packages\tornado\iostream.py:536
handle: <Handle BaseIOStream.write.<locals>.<lambda>(<Future cancelled>) at C:\Users\ch3njay\anaconda3\lib\site-packages\tornado\iostream.py:536>
Traceback (most recent call last):
  File "C:\Users\ch3njay\anaconda3\lib\asyncio\events.py", line 80, in _run
    self._context.run(self._callback, *self._args)
  File "C:\Users\ch3njay\anaconda3\lib\site-packages\tornado\iostream.py", line 536, in <lambda>
    future.add_done_callback(lambda f: f.exception())
asyncio.exceptions.CancelledError
2025-10-07 23:23:47,451 - ERROR - Exception in callback BaseIOStream.write.<locals>.<lambda>(<Future cancelled>) at C:\Users\ch3njay\anaconda3\lib\site-packages\tornado\iostream.py:536
handle: <Handle BaseIOStream.write.<locals>.<lambda>(<Future cancelled>) at C:\Users\ch3njay\anaconda3\lib\site-packages\tornado\iostream.py:536>
Traceback (most recent call last):
  File "C:\Users\ch3njay\anaconda3\lib\asyncio\events.py", line 80, in _run
    self._context.run(self._callback, *self._args)
  File "C:\Users\ch3njay\anaconda3\lib\site-packages\tornado\iostream.py", line 536, in <lambda>
    future.add_done_callback(lambda f: f.exception())
asyncio.exceptions.CancelledError
2025-10-07 23:23:47,451 - ERROR - Exception in callback BaseIOStream.write.<locals>.<lambda>(<Future cancelled>) at C:\Users\ch3njay\anaconda3\lib\site-packages\tornado\iostream.py:536
handle: <Handle BaseIOStream.write.<locals>.<lambda>(<Future cancelled>) at C:\Users\ch3njay\anaconda3\lib\site-packages\tornado\iostream.py:536>
Traceback (most recent call last):
  File "C:\Users\ch3njay\anaconda3\lib\asyncio\events.py", line 80, in _run
    self._context.run(self._callback, *self._args)
  File "C:\Users\ch3njay\anaconda3\lib\site-packages\tornado\iostream.py", line 536, in <lambda>
    future.add_done_callback(lambda f: f.exception())
asyncio.exceptions.CancelledError
2025-10-07 23:23:47,451 - ERROR - Exception in callback BaseIOStream.write.<locals>.<lambda>(<Future cancelled>) at C:\Users\ch3njay\anaconda3\lib\site-packages\tornado\iostream.py:536
handle: <Handle BaseIOStream.write.<locals>.<lambda>(<Future cancelled>) at C:\Users\ch3njay\anaconda3\lib\site-packages\tornado\iostream.py:536>
Traceback (most recent call last):
  File "C:\Users\ch3njay\anaconda3\lib\asyncio\events.py", line 80, in _run
    self._context.run(self._callback, *self._args)
  File "C:\Users\ch3njay\anaconda3\lib\site-packages\tornado\iostream.py", line 536, in <lambda>
    future.add_done_callback(lambda f: f.exception())
asyncio.exceptions.CancelledError
2025-10-07 23:23:47,452 - ERROR - Exception in callback BaseIOStream.write.<locals>.<lambda>(<Future cancelled>) at C:\Users\ch3njay\anaconda3\lib\site-packages\tornado\iostream.py:536
handle: <Handle BaseIOStream.write.<locals>.<lambda>(<Future cancelled>) at C:\Users\ch3njay\anaconda3\lib\site-packages\tornado\iostream.py:536>
Traceback (most recent call last):
  File "C:\Users\ch3njay\anaconda3\lib\asyncio\events.py", line 80, in _run
    self._context.run(self._callback, *self._args)
  File "C:\Users\ch3njay\anaconda3\lib\site-packages\tornado\iostream.py", line 536, in <lambda>
    future.add_done_callback(lambda f: f.exception())
asyncio.exceptions.CancelledError
2025-10-07 23:23:47,455 - ERROR - Exception in callback BaseIOStream.write.<locals>.<lambda>(<Future cancelled>) at C:\Users\ch3njay\anaconda3\lib\site-packages\tornado\iostream.py:536
handle: <Handle BaseIOStream.write.<locals>.<lambda>(<Future cancelled>) at C:\Users\ch3njay\anaconda3\lib\site-packages\tornado\iostream.py:536>
Traceback (most recent call last):
  File "C:\Users\ch3njay\anaconda3\lib\asyncio\events.py", line 80, in _run
    self._context.run(self._callback, *self._args)
  File "C:\Users\ch3njay\anaconda3\lib\site-packages\tornado\iostream.py", line 536, in <lambda>
    future.add_done_callback(lambda f: f.exception())
asyncio.exceptions.CancelledError
2025-10-07 23:23:47,456 - ERROR - Exception in callback BaseIOStream.write.<locals>.<lambda>(<Future cancelled>) at C:\Users\ch3njay\anaconda3\lib\site-packages\tornado\iostream.py:536
handle: <Handle BaseIOStream.write.<locals>.<lambda>(<Future cancelled>) at C:\Users\ch3njay\anaconda3\lib\site-packages\tornado\iostream.py:536>
Traceback (most recent call last):
  File "C:\Users\ch3njay\anaconda3\lib\asyncio\events.py", line 80, in _run
    self._context.run(self._callback, *self._args)
  File "C:\Users\ch3njay\anaconda3\lib\site-packages\tornado\iostream.py", line 536, in <lambda>
    future.add_done_callback(lambda f: f.exception())
asyncio.exceptions.CancelledError
2025-10-07 23:23:47,456 - ERROR - Exception in callback BaseIOStream.write.<locals>.<lambda>(<Future cancelled>) at C:\Users\ch3njay\anaconda3\lib\site-packages\tornado\iostream.py:536
handle: <Handle BaseIOStream.write.<locals>.<lambda>(<Future cancelled>) at C:\Users\ch3njay\anaconda3\lib\site-packages\tornado\iostream.py:536>
Traceback (most recent call last):
  File "C:\Users\ch3njay\anaconda3\lib\asyncio\events.py", line 80, in _run
    self._context.run(self._callback, *self._args)
  File "C:\Users\ch3njay\anaconda3\lib\site-packages\tornado\iostream.py", line 536, in <lambda>
    future.add_done_callback(lambda f: f.exception())
asyncio.exceptions.CancelledError
2025-10-07 23:23:47,456 - ERROR - Exception in callback BaseIOStream.write.<locals>.<lambda>(<Future cancelled>) at C:\Users\ch3njay\anaconda3\lib\site-packages\tornado\iostream.py:536
handle: <Handle BaseIOStream.write.<locals>.<lambda>(<Future cancelled>) at C:\Users\ch3njay\anaconda3\lib\site-packages\tornado\iostream.py:536>
Traceback (most recent call last):
  File "C:\Users\ch3njay\anaconda3\lib\asyncio\events.py", line 80, in _run
    self._context.run(self._callback, *self._args)
  File "C:\Users\ch3njay\anaconda3\lib\site-packages\tornado\iostream.py", line 536, in <lambda>
    future.add_done_callback(lambda f: f.exception())
asyncio.exceptions.CancelledError
2025-10-07 23:23:47,456 - ERROR - Exception in callback BaseIOStream.write.<locals>.<lambda>(<Future cancelled>) at C:\Users\ch3njay\anaconda3\lib\site-packages\tornado\iostream.py:536
handle: <Handle BaseIOStream.write.<locals>.<lambda>(<Future cancelled>) at C:\Users\ch3njay\anaconda3\lib\site-packages\tornado\iostream.py:536>
Traceback (most recent call last):
  File "C:\Users\ch3njay\anaconda3\lib\asyncio\events.py", line 80, in _run
    self._context.run(self._callback, *self._args)
  File "C:\Users\ch3njay\anaconda3\lib\site-packages\tornado\iostream.py", line 536, in <lambda>
    future.add_done_callback(lambda f: f.exception())
asyncio.exceptions.CancelledError
2025-10-07 23:23:47,457 - ERROR - Exception in callback BaseIOStream.write.<locals>.<lambda>(<Future cancelled>) at C:\Users\ch3njay\anaconda3\lib\site-packages\tornado\iostream.py:536
handle: <Handle BaseIOStream.write.<locals>.<lambda>(<Future cancelled>) at C:\Users\ch3njay\anaconda3\lib\site-packages\tornado\iostream.py:536>
Traceback (most recent call last):
  File "C:\Users\ch3njay\anaconda3\lib\asyncio\events.py", line 80, in _run
    self._context.run(self._callback, *self._args)
  File "C:\Users\ch3njay\anaconda3\lib\site-packages\tornado\iostream.py", line 536, in <lambda>
    future.add_done_callback(lambda f: f.exception())
asyncio.exceptions.CancelledError
2025-10-07 23:23:47,457 - ERROR - Exception in callback BaseIOStream.write.<locals>.<lambda>(<Future cancelled>) at C:\Users\ch3njay\anaconda3\lib\site-packages\tornado\iostream.py:536
handle: <Handle BaseIOStream.write.<locals>.<lambda>(<Future cancelled>) at C:\Users\ch3njay\anaconda3\lib\site-packages\tornado\iostream.py:536>
Traceback (most recent call last):
  File "C:\Users\ch3njay\anaconda3\lib\asyncio\events.py", line 80, in _run
    self._context.run(self._callback, *self._args)
  File "C:\Users\ch3njay\anaconda3\lib\site-packages\tornado\iostream.py", line 536, in <lambda>
    future.add_done_callback(lambda f: f.exception())
asyncio.exceptions.CancelledError
2025-10-07 23:23:47,457 - ERROR - Exception in callback BaseIOStream.write.<locals>.<lambda>(<Future cancelled>) at C:\Users\ch3njay\anaconda3\lib\site-packages\tornado\iostream.py:536
handle: <Handle BaseIOStream.write.<locals>.<lambda>(<Future cancelled>) at C:\Users\ch3njay\anaconda3\lib\site-packages\tornado\iostream.py:536>
Traceback (most recent call last):
  File "C:\Users\ch3njay\anaconda3\lib\asyncio\events.py", line 80, in _run
    self._context.run(self._callback, *self._args)
  File "C:\Users\ch3njay\anaconda3\lib\site-packages\tornado\iostream.py", line 536, in <lambda>
    future.add_done_callback(lambda f: f.exception())
asyncio.exceptions.CancelledError
2025-10-07 23:23:47,457 - ERROR - Exception in callback BaseIOStream.write.<locals>.<lambda>(<Future cancelled>) at C:\Users\ch3njay\anaconda3\lib\site-packages\tornado\iostream.py:536
handle: <Handle BaseIOStream.write.<locals>.<lambda>(<Future cancelled>) at C:\Users\ch3njay\anaconda3\lib\site-packages\tornado\iostream.py:536>
Traceback (most recent call last):
  File "C:\Users\ch3njay\anaconda3\lib\asyncio\events.py", line 80, in _run
    self._context.run(self._callback, *self._args)
  File "C:\Users\ch3njay\anaconda3\lib\site-packages\tornado\iostream.py", line 536, in <lambda>
    future.add_done_callback(lambda f: f.exception())
asyncio.exceptions.CancelledError
2025-10-07 23:23:47,465 - ERROR - Exception in callback BaseIOStream.write.<locals>.<lambda>(<Future cancelled>) at C:\Users\ch3njay\anaconda3\lib\site-packages\tornado\iostream.py:536
handle: <Handle BaseIOStream.write.<locals>.<lambda>(<Future cancelled>) at C:\Users\ch3njay\anaconda3\lib\site-packages\tornado\iostream.py:536>
Traceback (most recent call last):
  File "C:\Users\ch3njay\anaconda3\lib\asyncio\events.py", line 80, in _run
    self._context.run(self._callback, *self._args)
  File "C:\Users\ch3njay\anaconda3\lib\site-packages\tornado\iostream.py", line 536, in <lambda>
    future.add_done_callback(lambda f: f.exception())
asyncio.exceptions.CancelledError
2025-10-07 23:23:47,466 - ERROR - Exception in callback BaseIOStream.write.<locals>.<lambda>(<Future cancelled>) at C:\Users\ch3njay\anaconda3\lib\site-packages\tornado\iostream.py:536
handle: <Handle BaseIOStream.write.<locals>.<lambda>(<Future cancelled>) at C:\Users\ch3njay\anaconda3\lib\site-packages\tornado\iostream.py:536>
Traceback (most recent call last):
  File "C:\Users\ch3njay\anaconda3\lib\asyncio\events.py", line 80, in _run
    self._context.run(self._callback, *self._args)
  File "C:\Users\ch3njay\anaconda3\lib\site-packages\tornado\iostream.py", line 536, in <lambda>
    future.add_done_callback(lambda f: f.exception())
asyncio.exceptions.CancelledError
2025-10-07 23:23:47,467 - ERROR - Exception in callback BaseIOStream.write.<locals>.<lambda>(<Future cancelled>) at C:\Users\ch3njay\anaconda3\lib\site-packages\tornado\iostream.py:536
handle: <Handle BaseIOStream.write.<locals>.<lambda>(<Future cancelled>) at C:\Users\ch3njay\anaconda3\lib\site-packages\tornado\iostream.py:536>
Traceback (most recent call last):
  File "C:\Users\ch3njay\anaconda3\lib\asyncio\events.py", line 80, in _run
    self._context.run(self._callback, *self._args)
  File "C:\Users\ch3njay\anaconda3\lib\site-packages\tornado\iostream.py", line 536, in <lambda>
    future.add_done_callback(lambda f: f.exception())
asyncio.exceptions.CancelledError
2025-10-07 23:23:47,467 - ERROR - Exception in callback BaseIOStream.write.<locals>.<lambda>(<Future cancelled>) at C:\Users\ch3njay\anaconda3\lib\site-packages\tornado\iostream.py:536
handle: <Handle BaseIOStream.write.<locals>.<lambda>(<Future cancelled>) at C:\Users\ch3njay\anaconda3\lib\site-packages\tornado\iostream.py:536>
Traceback (most recent call last):
  File "C:\Users\ch3njay\anaconda3\lib\asyncio\events.py", line 80, in _run
    self._context.run(self._callback, *self._args)
  File "C:\Users\ch3njay\anaconda3\lib\site-packages\tornado\iostream.py", line 536, in <lambda>
    future.add_done_callback(lambda f: f.exception())
asyncio.exceptions.CancelledError
2025-10-07 23:23:47,469 - ERROR - Exception in callback BaseIOStream.write.<locals>.<lambda>(<Future cancelled>) at C:\Users\ch3njay\anaconda3\lib\site-packages\tornado\iostream.py:536
handle: <Handle BaseIOStream.write.<locals>.<lambda>(<Future cancelled>) at C:\Users\ch3njay\anaconda3\lib\site-packages\tornado\iostream.py:536>
Traceback (most recent call last):
  File "C:\Users\ch3njay\anaconda3\lib\asyncio\events.py", line 80, in _run
    self._context.run(self._callback, *self._args)
  File "C:\Users\ch3njay\anaconda3\lib\site-packages\tornado\iostream.py", line 536, in <lambda>
    future.add_done_callback(lambda f: f.exception())
asyncio.exceptions.CancelledError
2025-10-07 23:23:47,471 - ERROR - Exception in callback BaseIOStream.write.<locals>.<lambda>(<Future cancelled>) at C:\Users\ch3njay\anaconda3\lib\site-packages\tornado\iostream.py:536
handle: <Handle BaseIOStream.write.<locals>.<lambda>(<Future cancelled>) at C:\Users\ch3njay\anaconda3\lib\site-packages\tornado\iostream.py:536>
Traceback (most recent call last):
  File "C:\Users\ch3njay\anaconda3\lib\asyncio\events.py", line 80, in _run
    self._context.run(self._callback, *self._args)
  File "C:\Users\ch3njay\anaconda3\lib\site-packages\tornado\iostream.py", line 536, in <lambda>
    future.add_done_callback(lambda f: f.exception())
asyncio.exceptions.CancelledError
2025-10-07 23:23:47,471 - ERROR - Exception in callback BaseIOStream.write.<locals>.<lambda>(<Future cancelled>) at C:\Users\ch3njay\anaconda3\lib\site-packages\tornado\iostream.py:536
handle: <Handle BaseIOStream.write.<locals>.<lambda>(<Future cancelled>) at C:\Users\ch3njay\anaconda3\lib\site-packages\tornado\iostream.py:536>
Traceback (most recent call last):
  File "C:\Users\ch3njay\anaconda3\lib\asyncio\events.py", line 80, in _run
    self._context.run(self._callback, *self._args)
  File "C:\Users\ch3njay\anaconda3\lib\site-packages\tornado\iostream.py", line 536, in <lambda>
    future.add_done_callback(lambda f: f.exception())
asyncio.exceptions.CancelledError
2025-10-07 23:23:47,472 - ERROR - Exception in callback BaseIOStream.write.<locals>.<lambda>(<Future cancelled>) at C:\Users\ch3njay\anaconda3\lib\site-packages\tornado\iostream.py:536
handle: <Handle BaseIOStream.write.<locals>.<lambda>(<Future cancelled>) at C:\Users\ch3njay\anaconda3\lib\site-packages\tornado\iostream.py:536>
Traceback (most recent call last):
  File "C:\Users\ch3njay\anaconda3\lib\asyncio\events.py", line 80, in _run
    self._context.run(self._callback, *self._args)
  File "C:\Users\ch3njay\anaconda3\lib\site-packages\tornado\iostream.py", line 536, in <lambda>
    future.add_done_callback(lambda f: f.exception())
asyncio.exceptions.CancelledError
2025-10-07 23:23:47,472 - ERROR - Exception in callback BaseIOStream.write.<locals>.<lambda>(<Future cancelled>) at C:\Users\ch3njay\anaconda3\lib\site-packages\tornado\iostream.py:536
handle: <Handle BaseIOStream.write.<locals>.<lambda>(<Future cancelled>) at C:\Users\ch3njay\anaconda3\lib\site-packages\tornado\iostream.py:536>
Traceback (most recent call last):
  File "C:\Users\ch3njay\anaconda3\lib\asyncio\events.py", line 80, in _run
    self._context.run(self._callback, *self._args)
  File "C:\Users\ch3njay\anaconda3\lib\site-packages\tornado\iostream.py", line 536, in <lambda>
    future.add_done_callback(lambda f: f.exception())
asyncio.exceptions.CancelledError
2025-10-07 23:23:47,472 - ERROR - Exception in callback BaseIOStream.write.<locals>.<lambda>(<Future cancelled>) at C:\Users\ch3njay\anaconda3\lib\site-packages\tornado\iostream.py:536
handle: <Handle BaseIOStream.write.<locals>.<lambda>(<Future cancelled>) at C:\Users\ch3njay\anaconda3\lib\site-packages\tornado\iostream.py:536>
Traceback (most recent call last):
  File "C:\Users\ch3njay\anaconda3\lib\asyncio\events.py", line 80, in _run
    self._context.run(self._callback, *self._args)
  File "C:\Users\ch3njay\anaconda3\lib\site-packages\tornado\iostream.py", line 536, in <lambda>
    future.add_done_callback(lambda f: f.exception())
asyncio.exceptions.CancelledError
2025-10-07 23:23:47,472 - ERROR - Exception in callback BaseIOStream.write.<locals>.<lambda>(<Future cancelled>) at C:\Users\ch3njay\anaconda3\lib\site-packages\tornado\iostream.py:536
handle: <Handle BaseIOStream.write.<locals>.<lambda>(<Future cancelled>) at C:\Users\ch3njay\anaconda3\lib\site-packages\tornado\iostream.py:536>
Traceback (most recent call last):
  File "C:\Users\ch3njay\anaconda3\lib\asyncio\events.py", line 80, in _run
    self._context.run(self._callback, *self._args)
  File "C:\Users\ch3njay\anaconda3\lib\site-packages\tornado\iostream.py", line 536, in <lambda>
    future.add_done_callback(lambda f: f.exception())
asyncio.exceptions.CancelledError
2025-10-07 23:23:47,473 - ERROR - Exception in callback BaseIOStream.write.<locals>.<lambda>(<Future cancelled>) at C:\Users\ch3njay\anaconda3\lib\site-packages\tornado\iostream.py:536
handle: <Handle BaseIOStream.write.<locals>.<lambda>(<Future cancelled>) at C:\Users\ch3njay\anaconda3\lib\site-packages\tornado\iostream.py:536>
Traceback (most recent call last):
  File "C:\Users\ch3njay\anaconda3\lib\asyncio\events.py", line 80, in _run
    self._context.run(self._callback, *self._args)
  File "C:\Users\ch3njay\anaconda3\lib\site-packages\tornado\iostream.py", line 536, in <lambda>
    future.add_done_callback(lambda f: f.exception())
asyncio.exceptions.CancelledError
2025-10-07 23:23:47,473 - ERROR - Exception in callback BaseIOStream.write.<locals>.<lambda>(<Future cancelled>) at C:\Users\ch3njay\anaconda3\lib\site-packages\tornado\iostream.py:536
handle: <Handle BaseIOStream.write.<locals>.<lambda>(<Future cancelled>) at C:\Users\ch3njay\anaconda3\lib\site-packages\tornado\iostream.py:536>
Traceback (most recent call last):
  File "C:\Users\ch3njay\anaconda3\lib\asyncio\events.py", line 80, in _run
    self._context.run(self._callback, *self._args)
  File "C:\Users\ch3njay\anaconda3\lib\site-packages\tornado\iostream.py", line 536, in <lambda>
    future.add_done_callback(lambda f: f.exception())
asyncio.exceptions.CancelledError
2025-10-07 23:23:47,474 - ERROR - Exception in callback BaseIOStream.write.<locals>.<lambda>(<Future cancelled>) at C:\Users\ch3njay\anaconda3\lib\site-packages\tornado\iostream.py:536
handle: <Handle BaseIOStream.write.<locals>.<lambda>(<Future cancelled>) at C:\Users\ch3njay\anaconda3\lib\site-packages\tornado\iostream.py:536>
Traceback (most recent call last):
  File "C:\Users\ch3njay\anaconda3\lib\asyncio\events.py", line 80, in _run
    self._context.run(self._callback, *self._args)
  File "C:\Users\ch3njay\anaconda3\lib\site-packages\tornado\iostream.py", line 536, in <lambda>
    future.add_done_callback(lambda f: f.exception())
asyncio.exceptions.CancelledError
2025-10-07 23:23:47,474 - ERROR - Exception in callback BaseIOStream.write.<locals>.<lambda>(<Future cancelled>) at C:\Users\ch3njay\anaconda3\lib\site-packages\tornado\iostream.py:536
handle: <Handle BaseIOStream.write.<locals>.<lambda>(<Future cancelled>) at C:\Users\ch3njay\anaconda3\lib\site-packages\tornado\iostream.py:536>
Traceback (most recent call last):
  File "C:\Users\ch3njay\anaconda3\lib\asyncio\events.py", line 80, in _run
    self._context.run(self._callback, *self._args)
  File "C:\Users\ch3njay\anaconda3\lib\site-packages\tornado\iostream.py", line 536, in <lambda>
    future.add_done_callback(lambda f: f.exception())
asyncio.exceptions.CancelledError
2025-10-07 23:23:47,474 - ERROR - Exception in callback BaseIOStream.write.<locals>.<lambda>(<Future cancelled>) at C:\Users\ch3njay\anaconda3\lib\site-packages\tornado\iostream.py:536
handle: <Handle BaseIOStream.write.<locals>.<lambda>(<Future cancelled>) at C:\Users\ch3njay\anaconda3\lib\site-packages\tornado\iostream.py:536>
Traceback (most recent call last):
  File "C:\Users\ch3njay\anaconda3\lib\asyncio\events.py", line 80, in _run
    self._context.run(self._callback, *self._args)
  File "C:\Users\ch3njay\anaconda3\lib\site-packages\tornado\iostream.py", line 536, in <lambda>
    future.add_done_callback(lambda f: f.exception())
asyncio.exceptions.CancelledError
2025-10-07 23:23:47,474 - ERROR - Exception in callback BaseIOStream.write.<locals>.<lambda>(<Future cancelled>) at C:\Users\ch3njay\anaconda3\lib\site-packages\tornado\iostream.py:536
handle: <Handle BaseIOStream.write.<locals>.<lambda>(<Future cancelled>) at C:\Users\ch3njay\anaconda3\lib\site-packages\tornado\iostream.py:536>
Traceback (most recent call last):
  File "C:\Users\ch3njay\anaconda3\lib\asyncio\events.py", line 80, in _run
    self._context.run(self._callback, *self._args)
  File "C:\Users\ch3njay\anaconda3\lib\site-packages\tornado\iostream.py", line 536, in <lambda>
    future.add_done_callback(lambda f: f.exception())
asyncio.exceptions.CancelledError
2025-10-07 23:23:47,475 - ERROR - Exception in callback BaseIOStream.write.<locals>.<lambda>(<Future cancelled>) at C:\Users\ch3njay\anaconda3\lib\site-packages\tornado\iostream.py:536
handle: <Handle BaseIOStream.write.<locals>.<lambda>(<Future cancelled>) at C:\Users\ch3njay\anaconda3\lib\site-packages\tornado\iostream.py:536>
Traceback (most recent call last):
  File "C:\Users\ch3njay\anaconda3\lib\asyncio\events.py", line 80, in _run
    self._context.run(self._callback, *self._args)
  File "C:\Users\ch3njay\anaconda3\lib\site-packages\tornado\iostream.py", line 536, in <lambda>
    future.add_done_callback(lambda f: f.exception())
asyncio.exceptions.CancelledError
2025-10-07 23:23:47,475 - ERROR - Exception in callback BaseIOStream.write.<locals>.<lambda>(<Future cancelled>) at C:\Users\ch3njay\anaconda3\lib\site-packages\tornado\iostream.py:536
handle: <Handle BaseIOStream.write.<locals>.<lambda>(<Future cancelled>) at C:\Users\ch3njay\anaconda3\lib\site-packages\tornado\iostream.py:536>
Traceback (most recent call last):
  File "C:\Users\ch3njay\anaconda3\lib\asyncio\events.py", line 80, in _run
    self._context.run(self._callback, *self._args)
  File "C:\Users\ch3njay\anaconda3\lib\site-packages\tornado\iostream.py", line 536, in <lambda>
    future.add_done_callback(lambda f: f.exception())
asyncio.exceptions.CancelledError
2025-10-07 23:23:47,475 - ERROR - Exception in callback BaseIOStream.write.<locals>.<lambda>(<Future cancelled>) at C:\Users\ch3njay\anaconda3\lib\site-packages\tornado\iostream.py:536
handle: <Handle BaseIOStream.write.<locals>.<lambda>(<Future cancelled>) at C:\Users\ch3njay\anaconda3\lib\site-packages\tornado\iostream.py:536>
Traceback (most recent call last):
  File "C:\Users\ch3njay\anaconda3\lib\asyncio\events.py", line 80, in _run
    self._context.run(self._callback, *self._args)
  File "C:\Users\ch3njay\anaconda3\lib\site-packages\tornado\iostream.py", line 536, in <lambda>
    future.add_done_callback(lambda f: f.exception())
asyncio.exceptions.CancelledError
2025-10-07 23:23:47,475 - ERROR - Exception in callback BaseIOStream.write.<locals>.<lambda>(<Future cancelled>) at C:\Users\ch3njay\anaconda3\lib\site-packages\tornado\iostream.py:536
handle: <Handle BaseIOStream.write.<locals>.<lambda>(<Future cancelled>) at C:\Users\ch3njay\anaconda3\lib\site-packages\tornado\iostream.py:536>
Traceback (most recent call last):
  File "C:\Users\ch3njay\anaconda3\lib\asyncio\events.py", line 80, in _run
    self._context.run(self._callback, *self._args)
  File "C:\Users\ch3njay\anaconda3\lib\site-packages\tornado\iostream.py", line 536, in <lambda>
    future.add_done_callback(lambda f: f.exception())
asyncio.exceptions.CancelledError
2025-10-07 23:23:47,476 - ERROR - Exception in callback BaseIOStream.write.<locals>.<lambda>(<Future cancelled>) at C:\Users\ch3njay\anaconda3\lib\site-packages\tornado\iostream.py:536
handle: <Handle BaseIOStream.write.<locals>.<lambda>(<Future cancelled>) at C:\Users\ch3njay\anaconda3\lib\site-packages\tornado\iostream.py:536>
Traceback (most recent call last):
  File "C:\Users\ch3njay\anaconda3\lib\asyncio\events.py", line 80, in _run
    self._context.run(self._callback, *self._args)
  File "C:\Users\ch3njay\anaconda3\lib\site-packages\tornado\iostream.py", line 536, in <lambda>
    future.add_done_callback(lambda f: f.exception())
asyncio.exceptions.CancelledError
2025-10-07 23:23:47,476 - ERROR - Exception in callback BaseIOStream.write.<locals>.<lambda>(<Future cancelled>) at C:\Users\ch3njay\anaconda3\lib\site-packages\tornado\iostream.py:536
handle: <Handle BaseIOStream.write.<locals>.<lambda>(<Future cancelled>) at C:\Users\ch3njay\anaconda3\lib\site-packages\tornado\iostream.py:536>
Traceback (most recent call last):
  File "C:\Users\ch3njay\anaconda3\lib\asyncio\events.py", line 80, in _run
    self._context.run(self._callback, *self._args)
  File "C:\Users\ch3njay\anaconda3\lib\site-packages\tornado\iostream.py", line 536, in <lambda>
    future.add_done_callback(lambda f: f.exception())
asyncio.exceptions.CancelledError
2025-10-07 23:23:47,476 - ERROR - Exception in callback BaseIOStream.write.<locals>.<lambda>(<Future cancelled>) at C:\Users\ch3njay\anaconda3\lib\site-packages\tornado\iostream.py:536
handle: <Handle BaseIOStream.write.<locals>.<lambda>(<Future cancelled>) at C:\Users\ch3njay\anaconda3\lib\site-packages\tornado\iostream.py:536>
Traceback (most recent call last):
  File "C:\Users\ch3njay\anaconda3\lib\asyncio\events.py", line 80, in _run
    self._context.run(self._callback, *self._args)
  File "C:\Users\ch3njay\anaconda3\lib\site-packages\tornado\iostream.py", line 536, in <lambda>
    future.add_done_callback(lambda f: f.exception())
asyncio.exceptions.CancelledError
2025-10-07 23:23:47,476 - ERROR - Exception in callback BaseIOStream.write.<locals>.<lambda>(<Future cancelled>) at C:\Users\ch3njay\anaconda3\lib\site-packages\tornado\iostream.py:536
handle: <Handle BaseIOStream.write.<locals>.<lambda>(<Future cancelled>) at C:\Users\ch3njay\anaconda3\lib\site-packages\tornado\iostream.py:536>
Traceback (most recent call last):
  File "C:\Users\ch3njay\anaconda3\lib\asyncio\events.py", line 80, in _run
    self._context.run(self._callback, *self._args)
  File "C:\Users\ch3njay\anaconda3\lib\site-packages\tornado\iostream.py", line 536, in <lambda>
    future.add_done_callback(lambda f: f.exception())
asyncio.exceptions.CancelledError
2025-10-07 23:23:47,477 - ERROR - Exception in callback BaseIOStream.write.<locals>.<lambda>(<Future cancelled>) at C:\Users\ch3njay\anaconda3\lib\site-packages\tornado\iostream.py:536
handle: <Handle BaseIOStream.write.<locals>.<lambda>(<Future cancelled>) at C:\Users\ch3njay\anaconda3\lib\site-packages\tornado\iostream.py:536>
Traceback (most recent call last):
  File "C:\Users\ch3njay\anaconda3\lib\asyncio\events.py", line 80, in _run
    self._context.run(self._callback, *self._args)
  File "C:\Users\ch3njay\anaconda3\lib\site-packages\tornado\iostream.py", line 536, in <lambda>
    future.add_done_callback(lambda f: f.exception())
asyncio.exceptions.CancelledError
2025-10-07 23:23:47,477 - ERROR - Exception in callback BaseIOStream.write.<locals>.<lambda>(<Future cancelled>) at C:\Users\ch3njay\anaconda3\lib\site-packages\tornado\iostream.py:536
handle: <Handle BaseIOStream.write.<locals>.<lambda>(<Future cancelled>) at C:\Users\ch3njay\anaconda3\lib\site-packages\tornado\iostream.py:536>
Traceback (most recent call last):
  File "C:\Users\ch3njay\anaconda3\lib\asyncio\events.py", line 80, in _run
    self._context.run(self._callback, *self._args)
  File "C:\Users\ch3njay\anaconda3\lib\site-packages\tornado\iostream.py", line 536, in <lambda>
    future.add_done_callback(lambda f: f.exception())
asyncio.exceptions.CancelledError
2025-10-07 23:23:47,477 - ERROR - Exception in callback BaseIOStream.write.<locals>.<lambda>(<Future cancelled>) at C:\Users\ch3njay\anaconda3\lib\site-packages\tornado\iostream.py:536
handle: <Handle BaseIOStream.write.<locals>.<lambda>(<Future cancelled>) at C:\Users\ch3njay\anaconda3\lib\site-packages\tornado\iostream.py:536>
Traceback (most recent call last):
  File "C:\Users\ch3njay\anaconda3\lib\asyncio\events.py", line 80, in _run
    self._context.run(self._callback, *self._args)
  File "C:\Users\ch3njay\anaconda3\lib\site-packages\tornado\iostream.py", line 536, in <lambda>
    future.add_done_callback(lambda f: f.exception())
asyncio.exceptions.CancelledError
2025-10-07 23:23:47,477 - ERROR - Exception in callback BaseIOStream.write.<locals>.<lambda>(<Future cancelled>) at C:\Users\ch3njay\anaconda3\lib\site-packages\tornado\iostream.py:536
handle: <Handle BaseIOStream.write.<locals>.<lambda>(<Future cancelled>) at C:\Users\ch3njay\anaconda3\lib\site-packages\tornado\iostream.py:536>
Traceback (most recent call last):
  File "C:\Users\ch3njay\anaconda3\lib\asyncio\events.py", line 80, in _run
    self._context.run(self._callback, *self._args)
  File "C:\Users\ch3njay\anaconda3\lib\site-packages\tornado\iostream.py", line 536, in <lambda>
    future.add_done_callback(lambda f: f.exception())
asyncio.exceptions.CancelledError
2025-10-07 23:23:47,477 - ERROR - Exception in callback BaseIOStream.write.<locals>.<lambda>(<Future cancelled>) at C:\Users\ch3njay\anaconda3\lib\site-packages\tornado\iostream.py:536
handle: <Handle BaseIOStream.write.<locals>.<lambda>(<Future cancelled>) at C:\Users\ch3njay\anaconda3\lib\site-packages\tornado\iostream.py:536>
Traceback (most recent call last):
  File "C:\Users\ch3njay\anaconda3\lib\asyncio\events.py", line 80, in _run
    self._context.run(self._callback, *self._args)
  File "C:\Users\ch3njay\anaconda3\lib\site-packages\tornado\iostream.py", line 536, in <lambda>
    future.add_done_callback(lambda f: f.exception())
asyncio.exceptions.CancelledError
2025-10-07 23:23:47,477 - ERROR - Exception in callback BaseIOStream.write.<locals>.<lambda>(<Future cancelled>) at C:\Users\ch3njay\anaconda3\lib\site-packages\tornado\iostream.py:536
handle: <Handle BaseIOStream.write.<locals>.<lambda>(<Future cancelled>) at C:\Users\ch3njay\anaconda3\lib\site-packages\tornado\iostream.py:536>
Traceback (most recent call last):
  File "C:\Users\ch3njay\anaconda3\lib\asyncio\events.py", line 80, in _run
    self._context.run(self._callback, *self._args)
  File "C:\Users\ch3njay\anaconda3\lib\site-packages\tornado\iostream.py", line 536, in <lambda>
    future.add_done_callback(lambda f: f.exception())
asyncio.exceptions.CancelledError
2025-10-07 23:23:47,478 - ERROR - Exception in callback BaseIOStream.write.<locals>.<lambda>(<Future cancelled>) at C:\Users\ch3njay\anaconda3\lib\site-packages\tornado\iostream.py:536
handle: <Handle BaseIOStream.write.<locals>.<lambda>(<Future cancelled>) at C:\Users\ch3njay\anaconda3\lib\site-packages\tornado\iostream.py:536>
Traceback (most recent call last):
  File "C:\Users\ch3njay\anaconda3\lib\asyncio\events.py", line 80, in _run
    self._context.run(self._callback, *self._args)
  File "C:\Users\ch3njay\anaconda3\lib\site-packages\tornado\iostream.py", line 536, in <lambda>
    future.add_done_callback(lambda f: f.exception())
asyncio.exceptions.CancelledError
2025-10-07 23:23:47,478 - ERROR - Exception in callback BaseIOStream.write.<locals>.<lambda>(<Future cancelled>) at C:\Users\ch3njay\anaconda3\lib\site-packages\tornado\iostream.py:536
handle: <Handle BaseIOStream.write.<locals>.<lambda>(<Future cancelled>) at C:\Users\ch3njay\anaconda3\lib\site-packages\tornado\iostream.py:536>
Traceback (most recent call last):
  File "C:\Users\ch3njay\anaconda3\lib\asyncio\events.py", line 80, in _run
    self._context.run(self._callback, *self._args)
  File "C:\Users\ch3njay\anaconda3\lib\site-packages\tornado\iostream.py", line 536, in <lambda>
    future.add_done_callback(lambda f: f.exception())
asyncio.exceptions.CancelledError
2025-10-07 23:23:47,478 - ERROR - Exception in callback BaseIOStream.write.<locals>.<lambda>(<Future cancelled>) at C:\Users\ch3njay\anaconda3\lib\site-packages\tornado\iostream.py:536
handle: <Handle BaseIOStream.write.<locals>.<lambda>(<Future cancelled>) at C:\Users\ch3njay\anaconda3\lib\site-packages\tornado\iostream.py:536>
Traceback (most recent call last):
  File "C:\Users\ch3njay\anaconda3\lib\asyncio\events.py", line 80, in _run
    self._context.run(self._callback, *self._args)
  File "C:\Users\ch3njay\anaconda3\lib\site-packages\tornado\iostream.py", line 536, in <lambda>
    future.add_done_callback(lambda f: f.exception())
asyncio.exceptions.CancelledError
2025-10-07 23:23:47,478 - ERROR - Exception in callback BaseIOStream.write.<locals>.<lambda>(<Future cancelled>) at C:\Users\ch3njay\anaconda3\lib\site-packages\tornado\iostream.py:536
handle: <Handle BaseIOStream.write.<locals>.<lambda>(<Future cancelled>) at C:\Users\ch3njay\anaconda3\lib\site-packages\tornado\iostream.py:536>
Traceback (most recent call last):
  File "C:\Users\ch3njay\anaconda3\lib\asyncio\events.py", line 80, in _run
    self._context.run(self._callback, *self._args)
  File "C:\Users\ch3njay\anaconda3\lib\site-packages\tornado\iostream.py", line 536, in <lambda>
    future.add_done_callback(lambda f: f.exception())
asyncio.exceptions.CancelledError
2025-10-07 23:23:47,478 - ERROR - Exception in callback BaseIOStream.write.<locals>.<lambda>(<Future cancelled>) at C:\Users\ch3njay\anaconda3\lib\site-packages\tornado\iostream.py:536
handle: <Handle BaseIOStream.write.<locals>.<lambda>(<Future cancelled>) at C:\Users\ch3njay\anaconda3\lib\site-packages\tornado\iostream.py:536>
Traceback (most recent call last):
  File "C:\Users\ch3njay\anaconda3\lib\asyncio\events.py", line 80, in _run
    self._context.run(self._callback, *self._args)
  File "C:\Users\ch3njay\anaconda3\lib\site-packages\tornado\iostream.py", line 536, in <lambda>
    future.add_done_callback(lambda f: f.exception())
asyncio.exceptions.CancelledError
2025-10-07 23:23:47,479 - ERROR - Exception in callback BaseIOStream.write.<locals>.<lambda>(<Future cancelled>) at C:\Users\ch3njay\anaconda3\lib\site-packages\tornado\iostream.py:536
handle: <Handle BaseIOStream.write.<locals>.<lambda>(<Future cancelled>) at C:\Users\ch3njay\anaconda3\lib\site-packages\tornado\iostream.py:536>
Traceback (most recent call last):
  File "C:\Users\ch3njay\anaconda3\lib\asyncio\events.py", line 80, in _run
    self._context.run(self._callback, *self._args)
  File "C:\Users\ch3njay\anaconda3\lib\site-packages\tornado\iostream.py", line 536, in <lambda>
    future.add_done_callback(lambda f: f.exception())
asyncio.exceptions.CancelledError
2025-10-07 23:23:47,479 - ERROR - Exception in callback BaseIOStream.write.<locals>.<lambda>(<Future cancelled>) at C:\Users\ch3njay\anaconda3\lib\site-packages\tornado\iostream.py:536
handle: <Handle BaseIOStream.write.<locals>.<lambda>(<Future cancelled>) at C:\Users\ch3njay\anaconda3\lib\site-packages\tornado\iostream.py:536>
Traceback (most recent call last):
  File "C:\Users\ch3njay\anaconda3\lib\asyncio\events.py", line 80, in _run
    self._context.run(self._callback, *self._args)
  File "C:\Users\ch3njay\anaconda3\lib\site-packages\tornado\iostream.py", line 536, in <lambda>
    future.add_done_callback(lambda f: f.exception())
asyncio.exceptions.CancelledError
2025-10-07 23:23:47,479 - ERROR - Exception in callback BaseIOStream.write.<locals>.<lambda>(<Future cancelled>) at C:\Users\ch3njay\anaconda3\lib\site-packages\tornado\iostream.py:536
handle: <Handle BaseIOStream.write.<locals>.<lambda>(<Future cancelled>) at C:\Users\ch3njay\anaconda3\lib\site-packages\tornado\iostream.py:536>
Traceback (most recent call last):
  File "C:\Users\ch3njay\anaconda3\lib\asyncio\events.py", line 80, in _run
    self._context.run(self._callback, *self._args)
  File "C:\Users\ch3njay\anaconda3\lib\site-packages\tornado\iostream.py", line 536, in <lambda>
    future.add_done_callback(lambda f: f.exception())
asyncio.exceptions.CancelledError
2025-10-07 23:23:47,479 - ERROR - Exception in callback BaseIOStream.write.<locals>.<lambda>(<Future cancelled>) at C:\Users\ch3njay\anaconda3\lib\site-packages\tornado\iostream.py:536
handle: <Handle BaseIOStream.write.<locals>.<lambda>(<Future cancelled>) at C:\Users\ch3njay\anaconda3\lib\site-packages\tornado\iostream.py:536>
Traceback (most recent call last):
  File "C:\Users\ch3njay\anaconda3\lib\asyncio\events.py", line 80, in _run
    self._context.run(self._callback, *self._args)
  File "C:\Users\ch3njay\anaconda3\lib\site-packages\tornado\iostream.py", line 536, in <lambda>
    future.add_done_callback(lambda f: f.exception())
asyncio.exceptions.CancelledError
2025-10-07 23:23:47,479 - ERROR - Exception in callback BaseIOStream.write.<locals>.<lambda>(<Future cancelled>) at C:\Users\ch3njay\anaconda3\lib\site-packages\tornado\iostream.py:536
handle: <Handle BaseIOStream.write.<locals>.<lambda>(<Future cancelled>) at C:\Users\ch3njay\anaconda3\lib\site-packages\tornado\iostream.py:536>
Traceback (most recent call last):
  File "C:\Users\ch3njay\anaconda3\lib\asyncio\events.py", line 80, in _run
    self._context.run(self._callback, *self._args)
  File "C:\Users\ch3njay\anaconda3\lib\site-packages\tornado\iostream.py", line 536, in <lambda>
    future.add_done_callback(lambda f: f.exception())
asyncio.exceptions.CancelledError
2025-10-07 23:23:47,479 - ERROR - Exception in callback BaseIOStream.write.<locals>.<lambda>(<Future cancelled>) at C:\Users\ch3njay\anaconda3\lib\site-packages\tornado\iostream.py:536
handle: <Handle BaseIOStream.write.<locals>.<lambda>(<Future cancelled>) at C:\Users\ch3njay\anaconda3\lib\site-packages\tornado\iostream.py:536>
Traceback (most recent call last):
  File "C:\Users\ch3njay\anaconda3\lib\asyncio\events.py", line 80, in _run
    self._context.run(self._callback, *self._args)
  File "C:\Users\ch3njay\anaconda3\lib\site-packages\tornado\iostream.py", line 536, in <lambda>
    future.add_done_callback(lambda f: f.exception())
asyncio.exceptions.CancelledError
2025-10-07 23:23:47,480 - ERROR - Exception in callback BaseIOStream.write.<locals>.<lambda>(<Future cancelled>) at C:\Users\ch3njay\anaconda3\lib\site-packages\tornado\iostream.py:536
handle: <Handle BaseIOStream.write.<locals>.<lambda>(<Future cancelled>) at C:\Users\ch3njay\anaconda3\lib\site-packages\tornado\iostream.py:536>
Traceback (most recent call last):
  File "C:\Users\ch3njay\anaconda3\lib\asyncio\events.py", line 80, in _run
    self._context.run(self._callback, *self._args)
  File "C:\Users\ch3njay\anaconda3\lib\site-packages\tornado\iostream.py", line 536, in <lambda>
    future.add_done_callback(lambda f: f.exception())
asyncio.exceptions.CancelledError
2025-10-07 23:23:47,480 - ERROR - Exception in callback BaseIOStream.write.<locals>.<lambda>(<Future cancelled>) at C:\Users\ch3njay\anaconda3\lib\site-packages\tornado\iostream.py:536
handle: <Handle BaseIOStream.write.<locals>.<lambda>(<Future cancelled>) at C:\Users\ch3njay\anaconda3\lib\site-packages\tornado\iostream.py:536>
Traceback (most recent call last):
  File "C:\Users\ch3njay\anaconda3\lib\asyncio\events.py", line 80, in _run
    self._context.run(self._callback, *self._args)
  File "C:\Users\ch3njay\anaconda3\lib\site-packages\tornado\iostream.py", line 536, in <lambda>
    future.add_done_callback(lambda f: f.exception())
asyncio.exceptions.CancelledError
2025-10-07 23:23:47,481 - ERROR - Exception in callback BaseIOStream.write.<locals>.<lambda>(<Future cancelled>) at C:\Users\ch3njay\anaconda3\lib\site-packages\tornado\iostream.py:536
handle: <Handle BaseIOStream.write.<locals>.<lambda>(<Future cancelled>) at C:\Users\ch3njay\anaconda3\lib\site-packages\tornado\iostream.py:536>
Traceback (most recent call last):
  File "C:\Users\ch3njay\anaconda3\lib\asyncio\events.py", line 80, in _run
    self._context.run(self._callback, *self._args)
  File "C:\Users\ch3njay\anaconda3\lib\site-packages\tornado\iostream.py", line 536, in <lambda>
    future.add_done_callback(lambda f: f.exception())
asyncio.exceptions.CancelledError
2025-10-07 23:23:47,482 - ERROR - Exception in callback BaseIOStream.write.<locals>.<lambda>(<Future cancelled>) at C:\Users\ch3njay\anaconda3\lib\site-packages\tornado\iostream.py:536
handle: <Handle BaseIOStream.write.<locals>.<lambda>(<Future cancelled>) at C:\Users\ch3njay\anaconda3\lib\site-packages\tornado\iostream.py:536>
Traceback (most recent call last):
  File "C:\Users\ch3njay\anaconda3\lib\asyncio\events.py", line 80, in _run
    self._context.run(self._callback, *self._args)
  File "C:\Users\ch3njay\anaconda3\lib\site-packages\tornado\iostream.py", line 536, in <lambda>
    future.add_done_callback(lambda f: f.exception())
asyncio.exceptions.CancelledError
